Workbook

Sheet post-audit-active-backlog-statu
A1: BacklogId | B1: SourceId | C1: Category | D1: System | E1: Files | F1: HistoricalStatus | G1: ActiveStatus | H1: PostAuditBatch | I1: ReviewRowId | J1: ReviewStatus | K1: Action | L1: ReviewArtifact | M1: SourceEvidence | N1: Commit | O1: UpdatedAt | P1: Notes
A2: RB-03235 | B2: P10-F03235 | C2: Packet handlers | D2: XMLSpawner | E2: Data/Scripts/Custom/XMLSpawner/PacketHandlerOverrides.cs | F2: Ready | G2: Fixed | H2: POST-BATCH-A | I2: PHA-001 | J2: Fixed | K2: Patched XmlTextEntryBook.ContentChange and BaseContentChange to enforce writable/range/accessibility before accepting client page edits. | L2: docs/codebase-audit/outputs/post-batch-a-packet-handler-review.csv | M2: PacketHandlerOverrides.cs:41-57; XmlTextEntryBook.cs:194-317; BaseBook.cs:399-447 | N2: 3259f43b fix: harden packet handler paths | O2: 2026-06-06T16:41:26.8957053-05:00 | P2: Active post-audit overlay; canonical Phase 13 repair-backlog.csv is preserved as historical generated evidence.
A3: RB-03236 | B3: P10-F03236 | C3: Packet handlers | D3: XMLSpawner | E3: Data/Scripts/Custom/XMLSpawner/PacketHandlerOverrides.cs | F3: Ready | G3: Fixed | H3: POST-BATCH-A | I3: PHA-002 | J3: Fixed | K3: Patched XmlAttach.UseReq to restore core NextActionTime update after accepted use requests and core Counselor bypass threshold. | L3: docs/codebase-audit/outputs/post-batch-a-packet-handler-review.csv | M3: PacketHandlerOverrides.cs:59-64; XmlAttach.cs:2463-2567; PacketHandlers.cs:1487-1525 | N3: 3259f43b fix: harden packet handler paths | O3: 2026-06-06T16:41:26.8957053-05:00 | P3: Active post-audit overlay; canonical Phase 13 repair-backlog.csv is preserved as historical generated evidence.
A4: RB-03237 | B4: P10-F03237 | C4: Packet handlers | D4: XMLSpawner | E4: Data/Scripts/Custom/XMLSpawner/XmlTextEntryBook.cs | F4: Ready | G4: ReviewedNoChange | H4: POST-BATCH-A | I4: PHA-003 | J4: ReviewedNoChange | K4: Kept commented registration unchanged; active 0x66 review and fixes are recorded in PHA-001. | L4: docs/codebase-audit/outputs/post-batch-a-packet-handler-review.csv | M4: XmlTextEntryBook.cs:186-194; PacketHandlerOverrides.cs:41-57 | N4: 3259f43b fix: harden packet handler paths | O4: 2026-06-06T16:41:26.8957053-05:00 | P4: Active post-audit overlay; canonical Phase 13 repair-backlog.csv is preserved as historical generated evidence.
A5: RB-03238 | B5: P10-F03238 | C5: Packet handlers | D5: Items:Books | E5: Data/Scripts/Items/Books/BaseBook.cs | F5: Ready | G5: ReviewedNoChange | H5: POST-BATCH-A | I5: PHA-004 | J5: ReviewedNoChange | K5: No source change; guards match the expected BaseBook header edit path. | L5: docs/codebase-audit/outputs/post-batch-a-packet-handler-review.csv | M5: BaseBook.cs:337-397 | N5: 3259f43b fix: harden packet handler paths | O5: 2026-06-06T16:41:26.8957053-05:00 | P5: Active post-audit overlay; canonical Phase 13 repair-backlog.csv is preserved as historical generated evidence.
A6: RB-03239 | B6: P10-F03239 | C6: Packet handlers | D6: Items:Books | E6: Data/Scripts/Items/Books/BaseBook.cs | F6: Ready | G6: ReviewedNoChange | H6: POST-BATCH-A | I6: PHA-005 | J6: ReviewedNoChange | K6: No direct BaseBook source change; XMLSpawner delegate parity is fixed in PHA-001. | L6: docs/codebase-audit/outputs/post-batch-a-packet-handler-review.csv | M6: BaseBook.cs:337-447; PacketHandlerOverrides.cs:41-57 | N6: 3259f43b fix: harden packet handler paths | O6: 2026-06-06T16:41:26.8957053-05:00 | P6: Active post-audit overlay; canonical Phase 13 repair-backlog.csv is preserved as historical generated evidence.
A7: RB-03240 | B7: P10-F03240 | C7: Packet handlers | D7: Items:Books | E7: Data/Scripts/Items/Books/BaseBook.cs | F7: Ready | G7: ReviewedNoChange | H7: POST-BATCH-A | I7: PHA-006 | J7: ReviewedNoChange | K7: No source change; legacy handler has the same core access/range guard shape as HeaderChange. | L7: docs/codebase-audit/outputs/post-batch-a-packet-handler-review.csv | M7: BaseBook.cs:337-364 | N7: 3259f43b fix: harden packet handler paths | O7: 2026-06-06T16:41:26.8957053-05:00 | P7: Active post-audit overlay; canonical Phase 13 repair-backlog.csv is preserved as historical generated evidence.
A8: RB-03241 | B8: P10-F03241 | C8: Packet handlers | D8: Housing | E8: Data/Scripts/Items/Houses/Monopoly/Misc/GumpResponse.cs | F8: Ready | G8: Fixed | H8: POST-BATCH-A | I8: PHA-007 | J8: Fixed | K8: Patched DisplayGumpResponse to save and restore PacketReader position before m_Successor or core fallback. Deferred exact switch/text maximum parity because core Gump.m_Switches and m_TextEntries are internal to ServerCore. | L8: docs/codebase-audit/outputs/post-batch-a-packet-handler-review.csv | M8: GumpResponse.cs:19-101; PacketReader.cs:71-87; PacketHandlers.cs:1267-1365; Gump.cs:35-36 | N8: 3259f43b fix: harden packet handler paths | O8: 2026-06-06T16:41:26.8957053-05:00 | P8: Active post-audit overlay; canonical Phase 13 repair-backlog.csv is preserved as historical generated evidence.
A9: RB-03242 | B9: P10-F03242 | C9: Packet handlers | D9: Items:Misc | E9: Data/Scripts/Items/Misc/BulletinBoards.cs | F9: Ready | G9: ReviewedNoChange | H9: POST-BATCH-A | I9: PHA-008 | J9: ReviewedNoChange | K9: No source change; retained for later broader bulletin-board content/rate-limit review if needed. | L9: docs/codebase-audit/outputs/post-batch-a-packet-handler-review.csv | M9: BulletinBoards.cs:228-344 | N9: 3259f43b fix: harden packet handler paths | O9: 2026-06-06T16:41:26.8957053-05:00 | P9: Active post-audit overlay; canonical Phase 13 repair-backlog.csv is preserved as historical generated evidence.
A10: RB-03243 | B10: P10-F03243 | C10: Packet handlers | D10: Items:Misc | E10: Data/Scripts/Items/Misc/Games/Mahjong/MahjongPacketHandlers.cs | F10: Ready | G10: ReviewedNoChange | H10: POST-BATCH-A | I10: PHA-009 | J10: ReviewedNoChange | K10: No source change; review records game-state authorization as the controlling guard. | L10: docs/codebase-audit/outputs/post-batch-a-packet-handler-review.csv | M10: MahjongPacketHandlers.cs:36-267 | N10: 3259f43b fix: harden packet handler paths | O10: 2026-06-06T16:41:26.8957053-05:00 | P10: Active post-audit overlay; canonical Phase 13 repair-backlog.csv is preserved as historical generated evidence.
A11: RB-03244 | B11: P10-F03244 | C11: Packet handlers | D11: Items:Trades | E11: Data/Scripts/Items/Trades/Maps/MapItem.cs | F11: Ready | G11: ReviewedNoChange | H11: POST-BATCH-A | I11: PHA-010 | J11: ReviewedNoChange | K11: No source change; existing command methods provide the meaningful access/range gates. | L11: docs/codebase-audit/outputs/post-batch-a-packet-handler-review.csv | M11: MapItem.cs:394-435; MapItem.cs:545-585 | N11: 3259f43b fix: harden packet handler paths | O11: 2026-06-06T16:41:26.8957053-05:00 | P11: Active post-audit overlay; canonical Phase 13 repair-backlog.csv is preserved as historical generated evidence.
A12: RB-03245 | B12: P10-F03245 | C12: Packet handlers | D12: System:Chat | E12: Data/Scripts/System/Chat/General/Chat3Guild.cs | F12: Ready | G12: ReviewedNoChange | H12: POST-BATCH-A | I12: PHA-011 | J12: ReviewedNoChange | K12: No source change; downstream Channel.OnChat enforces CanChat for the ASCII guild path. | L12: docs/codebase-audit/outputs/post-batch-a-packet-handler-review.csv | M12: Chat3Guild.cs:15-40; Channel.cs:423-457; Guild.cs:69-79 | N12: 3259f43b fix: harden packet handler paths | O12: 2026-06-06T16:41:26.8957053-05:00 | P12: Active post-audit overlay; canonical Phase 13 repair-backlog.csv is preserved as historical generated evidence.
... A123: RB-00193 | B123: SERIAL-0132 | C123: Save compatibility | D123: Custom:Mobiles | E123: Data/Scripts/Custom/Mobiles/Spiders/SpiderQueen.cs | F123: Ready | G123: SafeNoChange | H123: POST-BATCH-B-03M | I123: SERIAL-0132 | J123: SafeNoChange | K123: No source change; SpiderQueen calls base Serialize/Deserialize, writes version 0, reads the same version integer, and has no custom serialized fields. | L123: docs/codebase-audit/outputs/post-batch-b-save-compatibility-triage.csv | M123: Data/Scripts/Custom/Mobiles/Spiders/SpiderQueen.cs:34-43 | N123: Recorded by current POST-BATCH-B-03M audit artifact commit | O123: 2026-06-06T22:53:28.9794767-05:00 | P123: Active post-audit overlay; canonical Phase 13 repair-backlog.csv is preserved as historical generated evidence.
A124: RB-00195 | B124: SERIAL-0134 | C124: WriteReadAlignment | D124: Custom:Mobiles | E124: Data/Scripts/Custom/Mobiles/Titans/FalseEarthGod.cs | F124: Ready | G124: SafeNoChange | H124: POST-BATCH-B-03N | I124: SERIAL-0134 | J124: Reviewed | K124: No source change; serializer already writes and reads only the version after base serialization. | L124: docs/codebase-audit/outputs/post-batch-b-save-compatibility-triage.csv | M124: Data/Scripts/Custom/Mobiles/Titans/FalseEarthGod.cs:38-47 | O124: 2026-06-06T23:00:23.0394448-05:00 | P124: Version-only mobile serializer; base Serialize/Deserialize calls and version write/read are aligned.
A125: RB-00197 | B125: SERIAL-0136 | C125: WriteReadAlignment | D125: Custom:Mobiles | E125: Data/Scripts/Custom/Mobiles/Titans/FalseFireGod.cs | F125: Ready | G125: SafeNoChange | H125: POST-BATCH-B-03N | I125: SERIAL-0136 | J125: Reviewed | K125: No source change; serializer already writes and reads only the version after base serialization. | L125: docs/codebase-audit/outputs/post-batch-b-save-compatibility-triage.csv | M125: Data/Scripts/Custom/Mobiles/Titans/FalseFireGod.cs:36-45 | O125: 2026-06-06T23:00:23.0394448-05:00 | P125: Version-only mobile serializer; base Serialize/Deserialize calls and version write/read are aligned.
A126: RB-00199 | B126: SERIAL-0138 | C126: WriteReadAlignment | D126: Custom:Mobiles | E126: Data/Scripts/Custom/Mobiles/Titans/FalseSeaGod.cs | F126: Ready | G126: SafeNoChange | H126: POST-BATCH-B-03N | I126: SERIAL-0138 | J126: Reviewed | K126: No source change; serializer already writes and reads only the version after base serialization. | L126: docs/codebase-audit/outputs/post-batch-b-save-compatibility-triage.csv | M126: Data/Scripts/Custom/Mobiles/Titans/FalseSeaGod.cs:36-45 | O126: 2026-06-06T23:00:23.0394448-05:00 | P126: Version-only mobile serializer; base Serialize/Deserialize calls and version write/read are aligned.
A127: RB-00201 | B127: SERIAL-0140 | C127: WriteReadAlignment | D127: Custom:Mobiles | E127: Data/Scripts/Custom/Mobiles/Titans/FalseWindGod.cs | F127: Ready | G127: SafeNoChange | H127: POST-BATCH-B-03N | I127: SERIAL-0140 | J127: Reviewed | K127: No source change; serializer already writes and reads only the version after base serialization. | L127: docs/codebase-audit/outputs/post-batch-b-save-compatibility-triage.csv | M127: Data/Scripts/Custom/Mobiles/Titans/FalseWindGod.cs:36-45 | O127: 2026-06-06T23:00:23.0394448-05:00 | P127: Version-only mobile serializer; base Serialize/Deserialize calls and version write/read are aligned.
A128: RB-00203 | B128: SERIAL-0142 | C128: WriteReadAlignment | D128: Custom:Mobiles | E128: Data/Scripts/Custom/Mobiles/Titans/Herculian.cs | F128: Ready | G128: SafeNoChange | H128: POST-BATCH-B-03N | I128: SERIAL-0142 | J128: Reviewed | K128: No source change; serializer already writes and reads only the version after base serialization. | L128: docs/codebase-audit/outputs/post-batch-b-save-compatibility-triage.csv | M128: Data/Scripts/Custom/Mobiles/Titans/Herculian.cs:36-45 | O128: 2026-06-06T23:00:23.0394448-05:00 | P128: Version-only mobile serializer; base Serialize/Deserialize calls and version write/read are aligned.
A129: RB-00205 | B129: SERIAL-0144 | C129: WriteReadAlignment | D129: Custom:Mobiles | E129: Data/Scripts/Custom/Mobiles/Undead/Beholder.cs | F129: Ready | G129: SafeNoChange | H129: POST-BATCH-B-03O | I129: SERIAL-0144 | J129: Reviewed | K129: No source change; serializer already writes and reads only the version after base serialization. | L129: docs/codebase-audit/outputs/post-batch-b-save-compatibility-triage.csv | M129: Data/Scripts/Custom/Mobiles/Undead/Beholder.cs:61-70 | O129: 2026-06-06T23:06:40.4235492-05:00 | P129: Version-only mobile serializer; base Serialize/Deserialize calls and version write/read are aligned.
A130: RB-00207 | B130: SERIAL-0146 | C130: WriteReadAlignment | D130: Custom:Mobiles | E130: Data/Scripts/Custom/Mobiles/Undead/CryptKeeper.cs | F130: Ready | G130: SafeNoChange | H130: POST-BATCH-B-03O | I130: SERIAL-0146 | J130: Reviewed | K130: No source change; serializer already writes and reads only the version after base serialization. | L130: docs/codebase-audit/outputs/post-batch-b-save-compatibility-triage.csv | M130: Data/Scripts/Custom/Mobiles/Undead/CryptKeeper.cs:55-64 | O130: 2026-06-06T23:06:40.4235492-05:00 | P130: Version-only mobile serializer; base Serialize/Deserialize calls and version write/read are aligned.
A131: RB-00209 | B131: SERIAL-0148 | C131: WriteReadAlignment | D131: Custom:Mobiles | E131: Data/Scripts/Custom/Mobiles/Undead/EvilDruid.cs | F131: Ready | G131: SafeNoChange | H131: POST-BATCH-B-03O | I131: SERIAL-0148 | J131: Reviewed | K131: No source change; serializer already writes and reads only the version after base serialization. | L131: docs/codebase-audit/outputs/post-batch-b-save-compatibility-triage.csv | M131: Data/Scripts/Custom/Mobiles/Undead/EvilDruid.cs:35-44 | O131: 2026-06-06T23:06:40.4235492-05:00 | P131: Version-only mobile serializer; base Serialize/Deserialize calls and version write/read are aligned.
A132: RB-00211 | B132: SERIAL-0150 | C132: WriteReadAlignment | D132: Custom:Mobiles | E132: Data/Scripts/Custom/Mobiles/Undead/GhostOfLadyEverdear.cs | F132: Ready | G132: SafeNoChange | H132: POST-BATCH-B-03O | I132: SERIAL-0150 | J132: Reviewed | K132: No source change; serializer already writes and reads only the version after base serialization. | L132: docs/codebase-audit/outputs/post-batch-b-save-compatibility-triage.csv | M132: Data/Scripts/Custom/Mobiles/Undead/GhostOfLadyEverdear.cs:50-59 | O132: 2026-06-06T23:06:40.4235492-05:00 | P132: Version-only mobile serializer; base Serialize/Deserialize calls and version write/read are aligned.
A133: RB-00213 | B133: SERIAL-0152 | C133: WriteReadAlignment | D133: Custom:Mobiles | E133: Data/Scripts/Custom/Mobiles/Undead/Honorguard.cs | F133: Ready | G133: SafeNoChange | H133: POST-BATCH-B-03O | I133: SERIAL-0152 | J133: Reviewed | K133: No source change; serializer already writes and reads only the version after base serialization. | L133: docs/codebase-audit/outputs/post-batch-b-save-compatibility-triage.csv | M133: Data/Scripts/Custom/Mobiles/Undead/Honorguard.cs:77-86 | O133: 2026-06-06T23:06:40.4235492-05:00 | P133: Version-only mobile serializer; base Serialize/Deserialize calls and version write/read are aligned.
A134: RB-00215 | B134: SERIAL-0154 | C134: WriteReadAlignment | D134: Custom:Mobiles | E134: Data/Scripts/Custom/Mobiles/Undead/OldKingWolfgang.cs | F134: Ready | G134: SafeNoChange | H134: POST-BATCH-B-03O | I134: SERIAL-0154 | J134: Reviewed | K134: No source change; serializer already writes and reads only the version after base serialization. | L134: docs/codebase-audit/outputs/post-batch-b-save-compatibility-triage.csv | M134: Data/Scripts/Custom/Mobiles/Undead/OldKingWolfgang.cs:38-47 | O134: 2026-06-06T23:06:40.4235492-05:00 | P134: Version-only mobile serializer; base Serialize/Deserialize calls and version write/read are aligned.
A135: RB-00217 | B135: SERIAL-0156 | C135: WriteReadAlignment | D135: Custom:Mobiles | E135: Data/Scripts/Custom/Mobiles/Undead/Rattlebones.cs | F135: Ready | G135: SafeNoChange | H135: POST-BATCH-B-03O | I135: SERIAL-0156 | J135: Reviewed | K135: No source change; serializer already writes and reads only the version after base serialization. | L135: docs/codebase-audit/outputs/post-batch-b-save-compatibility-triage.csv | M135: Data/Scripts/Custom/Mobiles/Undead/Rattlebones.cs:56-65 | O135: 2026-06-06T23:06:40.4235492-05:00 | P135: Version-only mobile serializer; base Serialize/Deserialize calls and version write/read are aligned.
... A303: RB-01557 | B303: SERIAL-1496 | C303: WriteReadAlignment | D303: System:Regions | E303: Data/Scripts/System/Regions/Spawning/SpawnEntry.cs | F303: Ready | G303: FalsePositive | H303: POST-BATCH-B-33A | I303: SERIAL-1496 | J303: Reviewed | K303: No source change; generated finding is extractor noise for a SpawnEntry helper serializer. SpawnPersistence writes the parent version and calls SpawnEntry.Serialize, and SpawnEntry.Deserialize(reader, version) or SpawnEntry.Remove(reader, version) consumes the paired helper payload. | L303: docs/codebase-audit/outputs/post-batch-b-save-compatibility-triage.csv | M303: Data/Scripts/System/Regions/Spawning/SpawnPersistence.cs:39-70; Data/Scripts/System/Regions/Spawning/SpawnEntry.cs:277-361 | O303: 2026-06-08T01:51:02.7822737-05:00 | P303: SpawnEntry is not an Item/Mobile override serializer; base-call and missing-reader findings are not applicable to this helper persistence shape.
A304: RB-01877 | B304: P10-F01877 | C304: Runtime hooks | D304: XMLSpawner | E304: Data/Scripts/Custom/XMLSpawner/PacketHandlerOverrides.cs | F304: Ready | G304: Fixed | H304: POST-BATCH-C-01A | I304: PHC-001 | J304: Fixed | K304: No new source change; prior POST-BATCH-A source fix already addressed this runtime hook row: Patched XmlTextEntryBook.ContentChange and BaseContentChange to enforce writable/range/accessibility before accepting client page edits. | L304: docs/codebase-audit/outputs/post-batch-c-runtime-hooks-player-mobile-review.csv | M304: PacketHandlerOverrides.cs:41-57; XmlTextEntryBook.cs:194-317; BaseBook.cs:399-447 | N304: Recorded by current POST-BATCH-C-01A audit artifact commit | O304: 2026-06-08T15:41:13.9877742-05:00 | P304: Mapped to PHA-001 in POST-BATCH-A.
A305: RB-01878 | B305: P10-F01878 | C305: Runtime hooks | D305: XMLSpawner | E305: Data/Scripts/Custom/XMLSpawner/PacketHandlerOverrides.cs | F305: Ready | G305: Fixed | H305: POST-BATCH-C-01A | I305: PHC-002 | J305: Fixed | K305: No new source change; prior POST-BATCH-A source fix already addressed this runtime hook row: Patched XmlAttach.UseReq to restore core NextActionTime update after accepted use requests and core Counselor bypass threshold. | L305: docs/codebase-audit/outputs/post-batch-c-runtime-hooks-player-mobile-review.csv | M305: PacketHandlerOverrides.cs:59-64; XmlAttach.cs:2463-2567; PacketHandlers.cs:1487-1525 | N305: Recorded by current POST-BATCH-C-01A audit artifact commit | O305: 2026-06-08T15:41:13.9877742-05:00 | P305: Mapped to PHA-002 in POST-BATCH-A.
A306: RB-01879 | B306: P10-F01879 | C306: Runtime hooks | D306: XMLSpawner | E306: Data/Scripts/Custom/XMLSpawner/XmlTextEntryBook.cs | F306: Ready | G306: ReviewedNoChange | H306: POST-BATCH-C-01A | I306: PHC-003 | J306: ReviewedNoChange | K306: No source change; prior POST-BATCH-A packet-handler review found existing guards acceptable for this runtime hook row: Kept commented registration unchanged; active 0x66 review and fixes are recorded in PHA-001. | L306: docs/codebase-audit/outputs/post-batch-c-runtime-hooks-player-mobile-review.csv | M306: XmlTextEntryBook.cs:186-194; PacketHandlerOverrides.cs:41-57 | N306: Recorded by current POST-BATCH-C-01A audit artifact commit | O306: 2026-06-08T15:41:13.9877742-05:00 | P306: Mapped to PHA-003 in POST-BATCH-A.
A307: RB-01880 | B307: P10-F01880 | C307: Runtime hooks | D307: Items:Books | E307: Data/Scripts/Items/Books/BaseBook.cs | F307: Ready | G307: ReviewedNoChange | H307: POST-BATCH-C-01A | I307: PHC-004 | J307: ReviewedNoChange | K307: No source change; prior POST-BATCH-A packet-handler review found existing guards acceptable for this runtime hook row: No source change; guards match the expected BaseBook header edit path. | L307: docs/codebase-audit/outputs/post-batch-c-runtime-hooks-player-mobile-review.csv | M307: BaseBook.cs:337-397 | N307: Recorded by current POST-BATCH-C-01A audit artifact commit | O307: 2026-06-08T15:41:13.9877742-05:00 | P307: Mapped to PHA-004 in POST-BATCH-A.
A308: RB-01881 | B308: P10-F01881 | C308: Runtime hooks | D308: Items:Books | E308: Data/Scripts/Items/Books/BaseBook.cs | F308: Ready | G308: ReviewedNoChange | H308: POST-BATCH-C-01A | I308: PHC-005 | J308: ReviewedNoChange | K308: No source change; prior POST-BATCH-A packet-handler review found existing guards acceptable for this runtime hook row: No direct BaseBook source change; XMLSpawner delegate parity is fixed in PHA-001. | L308: docs/codebase-audit/outputs/post-batch-c-runtime-hooks-player-mobile-review.csv | M308: BaseBook.cs:337-447; PacketHandlerOverrides.cs:41-57 | N308: Recorded by current POST-BATCH-C-01A audit artifact commit | O308: 2026-06-08T15:41:13.9877742-05:00 | P308: Mapped to PHA-005 in POST-BATCH-A.
A309: RB-01882 | B309: P10-F01882 | C309: Runtime hooks | D309: Items:Books | E309: Data/Scripts/Items/Books/BaseBook.cs | F309: Ready | G309: ReviewedNoChange | H309: POST-BATCH-C-01A | I309: PHC-006 | J309: ReviewedNoChange | K309: No source change; prior POST-BATCH-A packet-handler review found existing guards acceptable for this runtime hook row: No source change; legacy handler has the same core access/range guard shape as HeaderChange. | L309: docs/codebase-audit/outputs/post-batch-c-runtime-hooks-player-mobile-review.csv | M309: BaseBook.cs:337-364 | N309: Recorded by current POST-BATCH-C-01A audit artifact commit | O309: 2026-06-08T15:41:13.9877742-05:00 | P309: Mapped to PHA-006 in POST-BATCH-A.
A310: RB-01883 | B310: P10-F01883 | C310: Runtime hooks | D310: Housing | E310: Data/Scripts/Items/Houses/Monopoly/Misc/GumpResponse.cs | F310: Ready | G310: Fixed | H310: POST-BATCH-E-94A | I310: PHE-282 | J310: Fixed | K310: Patched Monopoly DisplayGumpResponse to complete the deferred exact switch/text maximum parity repair: it still saves and restores PacketReader position before m_Successor or core fallback, and now rejects switch counts above the matched gump's check/radio entry count, rejects text counts above the matched gump's text-entry count, and disconnects oversized text-entry payloads before relay allocation or OnResponse. | L310: docs/codebase-audit/outputs/post-batch-e-hooks-gumps-commands-regions-review.csv | M310: Data/Scripts/Items/Houses/Monopoly/Misc/GumpResponse.cs:19-142; Data/System/Source/Network/PacketHandlers.cs:1267-1327; Data/System/Source/Gumps/Gump.cs:35-36;530-531; Data/System/Source/Gumps/GumpCheck.cs:103-114; Data/System/Source/Gumps/GumpRadio.cs:103-114; Data/System/Source/Gumps/GumpTextEntry.cs:113-124; Data/System/Source/Gumps/GumpTextEntryLimited.cs:123-135 | N310: d75479ea and current POST-BATCH-E-94A source fix commit | O310: 2026-06-09T23:04:31.0536900-05:00 | P310: Supersedes the POST-BATCH-C-01A active overlay row for RB-01883; mapped to PHA-007 in POST-BATCH-A.
A311: RB-01884 | B311: P10-F01884 | C311: Runtime hooks | D311: Items:Misc | E311: Data/Scripts/Items/Misc/BulletinBoards.cs | F311: Ready | G311: ReviewedNoChange | H311: POST-BATCH-C-01A | I311: PHC-008 | J311: ReviewedNoChange | K311: No source change; prior POST-BATCH-A packet-handler review found existing guards acceptable for this runtime hook row: No source change; retained for later broader bulletin-board content/rate-limit review if needed. | L311: docs/codebase-audit/outputs/post-batch-c-runtime-hooks-player-mobile-review.csv | M311: BulletinBoards.cs:228-344 | N311: Recorded by current POST-BATCH-C-01A audit artifact commit | O311: 2026-06-08T15:41:13.9877742-05:00 | P311: Mapped to PHA-008 in POST-BATCH-A.
A312: RB-01885 | B312: P10-F01885 | C312: Runtime hooks | D312: Items:Misc | E312: Data/Scripts/Items/Misc/Games/Mahjong/MahjongPacketHandlers.cs | F312: Ready | G312: ReviewedNoChange | H312: POST-BATCH-C-01A | I312: PHC-009 | J312: ReviewedNoChange | K312: No source change; prior POST-BATCH-A packet-handler review found existing guards acceptable for this runtime hook row: No source change; review records game-state authorization as the controlling guard. | L312: docs/codebase-audit/outputs/post-batch-c-runtime-hooks-player-mobile-review.csv | M312: MahjongPacketHandlers.cs:36-267 | N312: Recorded by current POST-BATCH-C-01A audit artifact commit | O312: 2026-06-08T15:41:13.9877742-05:00 | P312: Mapped to PHA-009 in POST-BATCH-A.
A313: RB-01886 | B313: P10-F01886 | C313: Runtime hooks | D313: Items:Trades | E313: Data/Scripts/Items/Trades/Maps/MapItem.cs | F313: Ready | G313: ReviewedNoChange | H313: POST-BATCH-C-01A | I313: PHC-010 | J313: ReviewedNoChange | K313: No source change; prior POST-BATCH-A packet-handler review found existing guards acceptable for this runtime hook row: No source change; existing command methods provide the meaningful access/range gates. | L313: docs/codebase-audit/outputs/post-batch-c-runtime-hooks-player-mobile-review.csv | M313: MapItem.cs:394-435; MapItem.cs:545-585 | N313: Recorded by current POST-BATCH-C-01A audit artifact commit | O313: 2026-06-08T15:41:13.9877742-05:00 | P313: Mapped to PHA-010 in POST-BATCH-A.
A314: RB-01887 | B314: P10-F01887 | C314: Runtime hooks | D314: System:Chat | E314: Data/Scripts/System/Chat/General/Chat3Guild.cs | F314: Ready | G314: ReviewedNoChange | H314: POST-BATCH-C-01A | I314: PHC-011 | J314: ReviewedNoChange | K314: No source change; prior POST-BATCH-A packet-handler review found existing guards acceptable for this runtime hook row: No source change; downstream Channel.OnChat enforces CanChat for the ASCII guild path. | L314: docs/codebase-audit/outputs/post-batch-c-runtime-hooks-player-mobile-review.csv | M314: Chat3Guild.cs:15-40; Channel.cs:423-457; Guild.cs:69-79 | N314: Recorded by current POST-BATCH-C-01A audit artifact commit | O314: 2026-06-08T15:41:13.9877742-05:00 | P314: Mapped to PHA-011 in POST-BATCH-A.
A315: RB-01888 | B315: P10-F01888 | C315: Runtime hooks | D315: System:Chat | E315: Data/Scripts/System/Chat/General/Chat3Guild.cs | F315: Ready | G315: ReviewedNoChange | H315: POST-BATCH-C-01A | I315: PHC-012 | J315: ReviewedNoChange | K315: No source change; prior POST-BATCH-A packet-handler review found existing guards acceptable for this runtime hook row: No source change; explicit CanChat and downstream Channel.OnChat checks both protect guild chat. | L315: docs/codebase-audit/outputs/post-batch-c-runtime-hooks-player-mobile-review.csv | M315: Chat3Guild.cs:15-123; Channel.cs:423-457; Guild.cs:69-79 | N315: Recorded by current POST-BATCH-C-01A audit artifact commit | O315: 2026-06-08T15:41:13.9877742-05:00 | P315: Mapped to PHA-012 in POST-BATCH-A.
... A320: RB-01893 | B320: P10-F01893 | C320: Runtime hooks | D320: Regions | E320: Data/Scripts/System/Obsolete/Obsolete.cs | F320: Ready | G320: ReviewedNoChange | H320: POST-BATCH-C-01A | I320: PHC-017 | J320: ReviewedNoChange | K320: No source change; prior POST-BATCH-A packet-handler review found existing guards acceptable for this runtime hook row: No source change; broad legacy chat behavior remains deferred to chat-system review after P0 packet pass. | L320: docs/codebase-audit/outputs/post-batch-c-runtime-hooks-player-mobile-review.csv | M320: Obsolete.cs:6101-6153 | N320: Recorded by current POST-BATCH-C-01A audit artifact commit | O320: 2026-06-08T15:41:13.9877742-05:00 | P320: Mapped to PHA-017 in POST-BATCH-A.
A321: RB-05228 | B321: P10-F05228 | C321: PlayerMobile coupling | D321: Custom:Skill Stone | F321: Ready | G321: SafeNoChange | H321: POST-BATCH-C-01A | I321: PHC-018 | J321: SafeNoChange | K321: No source change; SkillStone writes a PlayerMobile reference through the Mobile writer overload and reads it back with reader.ReadMobile() cast to PlayerMobile, preserving the saved object-reference format. | L321: docs/codebase-audit/outputs/post-batch-c-runtime-hooks-player-mobile-review.csv | M321: Data/Scripts/Custom/Skill Stone/SkillStone.cs:168-199; serialization-register.csv Server.Items.SkillStone Writes/Reads | N321: Recorded by current POST-BATCH-C-01A audit artifact commit | O321: 2026-06-08T15:41:13.9877742-05:00 | P321: Keep namespace/type stable; future SkillStone changes should preserve assigned-player reference semantics.
...

Sheet Audit Dashboard
B1: POST-AUDIT | INSIGHTS DASHBOARD
B3: 2026-10-25 | FIX-09–15 code/regression complete; all three foundation batches await in-game Qwen acceptance. No deployment.
B5: RECORDS | F5: FIXED | J5: NO-CHANGE OUTCOMES | N5: DOMAIN-ONLY BLOCKERS
B6: =COUNTA('post-audit-active-backlog-statu'!$A$2:$A$6832) -> 6831 | F6: =COUNTIF('post-audit-active-backlog-statu'!$G$2:$G$6832,"Fixed") -> 957 | J6: =COUNTIF('post-audit-active-backlog-statu'!$G$2:$G$6832,"ReviewedNoChange")+COUNTIF('post-audit-active-backlog-statu'!$G$2:$G$6832,"SafeNoChange")+COUNTIF('post-audit-active-backlog-statu'!$G$2:$G$6832,"PolicyResolvedNoChange") -> 3700 | N6: =COUNTIF('post-audit-active-backlog-statu'!$G$2:$G$6832,"BlocksOnlyThisDomain") -> 7
B8: =COUNTA('Audit Analysis'!M5:M209)&" systems covered" -> 205 systems covered | F8: =TEXT(F6/B6,"0.0%")&" of all records" -> 14.0% of all records | J8: =TEXT(J6/B6,"0.0%")&" of all records" -> 54.2% of all records | N8: =TEXT(N6/B6,"0.0%")&" • scope-limited" -> 0.1% • scope-limited
B9: READOUT | Where to focus
B10: ="CONCENTRATION | "&'Audit Analysis'!F5&" + "&'Audit Analysis'!F6&" account for "&TEXT(SUM('Audit Analysis'!G5:G6)/B6,"0.0%")&" of records; prioritize these review surfaces." -> CONCENTRATION | Runtime hooks + Save compatibility account for 44.0% of records; prioritize these review surfaces.
B11: ="OUTCOMES | "&TEXT(J6/B6,"0.0%")&" are explicit no-change outcomes; "&TEXT(F6/B6,"0.0%")&" are Fixed. These are dispositions, not a closure rate." -> OUTCOMES | 54.2% are explicit no-change outcomes; 14.0% are Fixed. These are dispositions, not a closure rate.
B12: ="APPROVAL GATES | "&COUNTIF('post-audit-active-backlog-statu'!$J$2:$J$6832,"BlockedForReorganizationOnly")&" move/reorganization + "&COUNTIF('post-audit-active-backlog-statu'!$J$2:$J$6832,"BlockedForSerializerMigrationOnly")&" serializer-migration blockers. See linked records below." -> APPROVAL GATES | 6 move/reorganization + 1 serializer-migration blockers. See linked records below.
B13: ="SNAPSHOT TIMING | "&TEXT(SUMIFS('Audit Analysis'!U5:U16,'Audit Analysis'!T5:T16,"<"&DATE(2026,10,1)),"#,##0")&" records last updated before October; latest source date "&TEXT(MAX('Audit Analysis'!T5:T16),"mmm d, yyyy")&"." -> SNAPSHOT TIMING | 6,813 records last updated before October; latest source date Oct 25, 2026.
B14: ="DATA CHECKS | "&IF(COUNTIF('Audit Analysis'!C19:C27,"REVIEW")=0,"All 9 reconciliation / completeness checks pass.",COUNTIF('Audit Analysis'!C19:C27,"REVIEW")&" checks require review; see Audit Analysis.") -> DATA CHECKS | All 9 reconciliation / completeness checks pass.
B52: APPROVAL GATES | Click a record to inspect the source
B53: Blockers apply only to the named domain; ordinary maintenance may proceed within the source-defined boundaries.
B55: =HYPERLINK("#'post-audit-active-backlog-statu'!A1620",'post-audit-active-backlog-statu'!A1620&" | "&'post-audit-active-backlog-statu'!D1620&" | "&'post-audit-active-backlog-statu'!J1620) -> RB-06806 | PvP Consent | BlockedForReorganizationOnly
B56: =HYPERLINK("#'post-audit-active-backlog-statu'!A1622",'post-audit-active-backlog-statu'!A1622&" | "&'post-audit-active-backlog-statu'!D1622&" | "&'post-audit-active-backlog-statu'!J1622) -> RB-06808 | Invasion | BlockedForReorganizationOnly
B57: =HYPERLINK("#'post-audit-active-backlog-statu'!A1623",'post-audit-active-backlog-statu'!A1623&" | "&'post-audit-active-backlog-statu'!D1623&" | "&'post-audit-active-backlog-statu'!J1623) -> RB-06813 | XMLSpawner | BlockedForReorganizationOnly
B58: =HYPERLINK("#'post-audit-active-backlog-statu'!A1624",'post-audit-active-backlog-statu'!A1624&" | "&'post-audit-active-backlog-statu'!D1624&" | "&'post-audit-active-backlog-statu'!J1624) -> RB-06807 | Government | BlockedForReorganizationOnly
B59: =HYPERLINK("#'post-audit-active-backlog-statu'!A1625",'post-audit-active-backlog-statu'!A1625&" | "&'post-audit-active-backlog-statu'!D1625&" | "&'post-audit-active-backlog-statu'!J1625) -> RB-06803 | Offline Skill Training | BlockedForReorganizationOnly
B60: =HYPERLINK("#'post-audit-active-backlog-statu'!A1626",'post-audit-active-backlog-statu'!A1626&" | "&'post-audit-active-backlog-statu'!D1626&" | "&'post-audit-active-backlog-statu'!J1626) -> RB-06814 | Homestead | BlockedForReorganizationOnly
B61: =HYPERLINK("#'post-audit-active-backlog-statu'!A2137",'post-audit-active-backlog-statu'!A2137&" | "&'post-audit-active-backlog-statu'!D2137&" | "&'post-audit-active-backlog-statu'!J2137) -> RB-00724 | Items:Houses | BlockedForSerializerMigrationOnly
B63: INTERPRETATION & MAINTENANCE
B64: No-change = ReviewedNoChange + SafeNoChange + PolicyResolvedNoChange. Fixed uses ActiveStatus exactly; no closure rate is inferred.
B65: IntentionalLegacy, AcceptedFence, Documented and FalsePositive remain separate outcomes; a record is not necessarily a unique file.
B66: Update chart counts each record’s last timestamp—not daily throughput. Dates use the written calendar date; numeric Excel dates are included.
B67: Source: post-audit-active-backlog-status.csv | 6,831 records. Repair reports distinguish local verification from deployment.
B68: Audit Analysis contains all 17 categories, 205 systems, status definitions, history comparisons and visible quality checks. Source records are untouched.
B70: Workbook: post-audit-active-backlog-statu | Dashboard built 2026-10-17 | No owner, SLA or creation date supplied; no overdue metric inferred.

Sheet Audit Analysis
A1: AUDIT ANALYSIS | Live source-linked summaries
A2: 2026-10-25 | Native formulas, charts and filters preserved; counts and cached results reconciled against the CSV.
A4: Active status | B4: Records | C4: Share | D4: Interpretation | F4: Category | G4: Records | H4: Fixed | I4: No change | J4: Domain blockers | K4: Fixed share | M4: System | N4: Records | O4: Fixed | P4: No change | Q4: Domain blockers | R4: Fixed share | T4: Last update date | U4: Records
B5: =COUNTIF('post-audit-active-backlog-statu'!$G$2:$G$6832,A5) -> 2650 | C5: =B5/'Audit Dashboard'!$B$6 -> 0.38793734 | D5: Reviewed; no change | F5: Runtime hooks | G5: =COUNTIF('post-audit-active-backlog-statu'!$C$2:$C$6832,F5) -> 1557 | H5: =COUNTIFS('post-audit-active-backlog-statu'!$C$2:$C$6832,F5,'post-audit-active-backlog-statu'!$G$2:$G$6832,"Fixed") -> 252 | I5: =COUNTIFS('post-audit-active-backlog-statu'!$C$2:$C$6832,F5,'post-audit-active-backlog-statu'!$G$2:$G$6832,"ReviewedNoChange")+COUNTIFS('post-audit-active-backlog-statu'!$C$2:$C$6832,F5,'post-audit-active-backlog-statu'!$G$2:$G$6832,"SafeNoChange")+COUNTIFS('post-audit-active-backlog-statu'!$C$2:$C$6832,F5,'post-audit-active-backlog-statu'!$G$2:$G$6832,"PolicyResolvedNoChange") -> 1284 | J5: =COUNTIFS('post-audit-active-backlog-statu'!$C$2:$C$6832,F5,'post-audit-active-backlog-statu'!$G$2:$G$6832,"BlocksOnlyThisDomain") -> 0 | K5: =H5/G5 -> 0.16184971 | M5: Items:Magical | N5: =COUNTIF('post-audit-active-backlog-statu'!$D$2:$D$6832,M5) -> 999 | O5: =COUNTIFS('post-audit-active-backlog-statu'!$D$2:$D$6832,M5,'post-audit-active-backlog-statu'!$G$2:$G$6832,"Fixed") -> 8 | P5: =COUNTIFS('post-audit-active-backlog-statu'!$D$2:$D$6832,M5,'post-audit-active-backlog-statu'!$G$2:$G$6832,"ReviewedNoChange")+COUNTIFS('post-audit-active-backlog-statu'!$D$2:$D$6832,M5,'post-audit-active-backlog-statu'!$G$2:$G$6832,"SafeNoChange")+COUNTIFS('post-audit-active-backlog-statu'!$D$2:$D$6832,M5,'post-audit-active-backlog-statu'!$G$2:$G$6832,"PolicyResolvedNoChange") -> 216 | Q5: =COUNTIFS('post-audit-active-backlog-statu'!$D$2:$D$6832,M5,'post-audit-active-backlog-statu'!$G$2:$G$6832,"BlocksOnlyThisDomain") -> 0 | R5: =O5/N5 -> 0.008008008 | T5: 46179 | U5: =COUNTIF('post-audit-active-backlog-statu'!$O$2:$O$6832,TEXT(T5,"yyyy-mm-dd")&"*")+COUNTIFS('post-audit-active-backlog-statu'!$O$2:$O$6832,">="&T5,'post-audit-active-backlog-statu'!$O$2:$O$6832,"<"&T5+1) -> 203 | A5: ReviewedNoChange
B6: =COUNTIF('post-audit-active-backlog-statu'!$G$2:$G$6832,A6) -> 1395 | C6: =B6/'Audit Dashboard'!$B$6 -> 0.20421607 | D6: Legacy retained intentionally | F6: Save compatibility | G6: =COUNTIF('post-audit-active-backlog-statu'!$C$2:$C$6832,F6) -> 1446 | H6: =COUNTIFS('post-audit-active-backlog-statu'!$C$2:$C$6832,F6,'post-audit-active-backlog-statu'!$G$2:$G$6832,"Fixed") -> 1 | I6: =COUNTIFS('post-audit-active-backlog-statu'!$C$2:$C$6832,F6,'post-audit-active-backlog-statu'!$G$2:$G$6832,"ReviewedNoChange")+COUNTIFS('post-audit-active-backlog-statu'!$C$2:$C$6832,F6,'post-audit-active-backlog-statu'!$G$2:$G$6832,"SafeNoChange")+COUNTIFS('post-audit-active-backlog-statu'!$C$2:$C$6832,F6,'post-audit-active-backlog-statu'!$G$2:$G$6832,"PolicyResolvedNoChange") -> 500 | J6: =COUNTIFS('post-audit-active-backlog-statu'!$C$2:$C$6832,F6,'post-audit-active-backlog-statu'!$G$2:$G$6832,"BlocksOnlyThisDomain") -> 1 | K6: =H6/G6 -> 0.00069156293 | M6: System:Commands | N6: =COUNTIF('post-audit-active-backlog-statu'!$D$2:$D$6832,M6) -> 424 | O6: =COUNTIFS('post-audit-active-backlog-statu'!$D$2:$D$6832,M6,'post-audit-active-backlog-statu'!$G$2:$G$6832,"Fixed") -> 21 | P6: =COUNTIFS('post-audit-active-backlog-statu'!$D$2:$D$6832,M6,'post-audit-active-backlog-statu'!$G$2:$G$6832,"ReviewedNoChange")+COUNTIFS('post-audit-active-backlog-statu'!$D$2:$D$6832,M6,'post-audit-active-backlog-statu'!$G$2:$G$6832,"SafeNoChange")+COUNTIFS('post-audit-active-backlog-statu'!$D$2:$D$6832,M6,'post-audit-active-backlog-statu'!$G$2:$G$6832,"PolicyResolvedNoChange") -> 366 | Q6: =COUNTIFS('post-audit-active-backlog-statu'!$D$2:$D$6832,M6,'post-audit-active-backlog-statu'!$G$2:$G$6832,"BlocksOnlyThisDomain") -> 0 | R6: =O6/N6 -> 0.049528302 | T6: 46180 | U6: =COUNTIF('post-audit-active-backlog-statu'!$O$2:$O$6832,TEXT(T6,"yyyy-mm-dd")&"*")+COUNTIFS('post-audit-active-backlog-statu'!$O$2:$O$6832,">="&T6,'post-audit-active-backlog-statu'!$O$2:$O$6832,"<"&T6+1) -> 92 | A6: IntentionalLegacy
B7: =COUNTIF('post-audit-active-backlog-statu'!$G$2:$G$6832,A7) -> 957 | C7: =B7/'Audit Dashboard'!$B$6 -> 0.14009662 | D7: Fixed per active status | F7: Gump guards | G7: =COUNTIF('post-audit-active-backlog-statu'!$C$2:$C$6832,F7) -> 939 | H7: =COUNTIFS('post-audit-active-backlog-statu'!$C$2:$C$6832,F7,'post-audit-active-backlog-statu'!$G$2:$G$6832,"Fixed") -> 111 | I7: =COUNTIFS('post-audit-active-backlog-statu'!$C$2:$C$6832,F7,'post-audit-active-backlog-statu'!$G$2:$G$6832,"ReviewedNoChange")+COUNTIFS('post-audit-active-backlog-statu'!$C$2:$C$6832,F7,'post-audit-active-backlog-statu'!$G$2:$G$6832,"SafeNoChange")+COUNTIFS('post-audit-active-backlog-statu'!$C$2:$C$6832,F7,'post-audit-active-backlog-statu'!$G$2:$G$6832,"PolicyResolvedNoChange") -> 820 | J7: =COUNTIFS('post-audit-active-backlog-statu'!$C$2:$C$6832,F7,'post-audit-active-backlog-statu'!$G$2:$G$6832,"BlocksOnlyThisDomain") -> 0 | K7: =H7/G7 -> 0.11821086 | M7: Static Gump Tool | N7: =COUNTIF('post-audit-active-backlog-statu'!$D$2:$D$6832,M7) -> 355 | O7: =COUNTIFS('post-audit-active-backlog-statu'!$D$2:$D$6832,M7,'post-audit-active-backlog-statu'!$G$2:$G$6832,"Fixed") -> 23 | P7: =COUNTIFS('post-audit-active-backlog-statu'!$D$2:$D$6832,M7,'post-audit-active-backlog-statu'!$G$2:$G$6832,"ReviewedNoChange")+COUNTIFS('post-audit-active-backlog-statu'!$D$2:$D$6832,M7,'post-audit-active-backlog-statu'!$G$2:$G$6832,"SafeNoChange")+COUNTIFS('post-audit-active-backlog-statu'!$D$2:$D$6832,M7,'post-audit-active-backlog-statu'!$G$2:$G$6832,"PolicyResolvedNoChange") -> 322 | Q7: =COUNTIFS('post-audit-active-backlog-statu'!$D$2:$D$6832,M7,'post-audit-active-backlog-statu'!$G$2:$G$6832,"BlocksOnlyThisDomain") -> 0 | R7: =O7/N7 -> 0.064788732 | T7: 46181 | U7: =COUNTIF('post-audit-active-backlog-statu'!$O$2:$O$6832,TEXT(T7,"yyyy-mm-dd")&"*")+COUNTIFS('post-audit-active-backlog-statu'!$O$2:$O$6832,">="&T7,'post-audit-active-backlog-statu'!$O$2:$O$6832,"<"&T7+1) -> 439 | A7: Fixed
B8: =COUNTIF('post-audit-active-backlog-statu'!$G$2:$G$6832,A8) -> 678 | C8: =B8/'Audit Dashboard'!$B$6 -> 0.099253404 | D8: Safe; no change | F8: Legacy compatibility | G8: =COUNTIF('post-audit-active-backlog-statu'!$C$2:$C$6832,F8) -> 659 | H8: =COUNTIFS('post-audit-active-backlog-statu'!$C$2:$C$6832,F8,'post-audit-active-backlog-statu'!$G$2:$G$6832,"Fixed") -> 0 | I8: =COUNTIFS('post-audit-active-backlog-statu'!$C$2:$C$6832,F8,'post-audit-active-backlog-statu'!$G$2:$G$6832,"ReviewedNoChange")+COUNTIFS('post-audit-active-backlog-statu'!$C$2:$C$6832,F8,'post-audit-active-backlog-statu'!$G$2:$G$6832,"SafeNoChange")+COUNTIFS('post-audit-active-backlog-statu'!$C$2:$C$6832,F8,'post-audit-active-backlog-statu'!$G$2:$G$6832,"PolicyResolvedNoChange") -> 0 | J8: =COUNTIFS('post-audit-active-backlog-statu'!$C$2:$C$6832,F8,'post-audit-active-backlog-statu'!$G$2:$G$6832,"BlocksOnlyThisDomain") -> 0 | K8: =H8/G8 -> 0 | M8: XMLSpawner | N8: =COUNTIF('post-audit-active-backlog-statu'!$D$2:$D$6832,M8) -> 284 | O8: =COUNTIFS('post-audit-active-backlog-statu'!$D$2:$D$6832,M8,'post-audit-active-backlog-statu'!$G$2:$G$6832,"Fixed") -> 72 | P8: =COUNTIFS('post-audit-active-backlog-statu'!$D$2:$D$6832,M8,'post-audit-active-backlog-statu'!$G$2:$G$6832,"ReviewedNoChange")+COUNTIFS('post-audit-active-backlog-statu'!$D$2:$D$6832,M8,'post-audit-active-backlog-statu'!$G$2:$G$6832,"SafeNoChange")+COUNTIFS('post-audit-active-backlog-statu'!$D$2:$D$6832,M8,'post-audit-active-backlog-statu'!$G$2:$G$6832,"PolicyResolvedNoChange") -> 183 | Q8: =COUNTIFS('post-audit-active-backlog-statu'!$D$2:$D$6832,M8,'post-audit-active-backlog-statu'!$G$2:$G$6832,"BlocksOnlyThisDomain") -> 1 | R8: =O8/N8 -> 0.25352113 | T8: 46182 | U8: =COUNTIF('post-audit-active-backlog-statu'!$O$2:$O$6832,TEXT(T8,"yyyy-mm-dd")&"*")+COUNTIFS('post-audit-active-backlog-statu'!$O$2:$O$6832,">="&T8,'post-audit-active-backlog-statu'!$O$2:$O$6832,"<"&T8+1) -> 274 | A8: SafeNoChange
B9: =COUNTIF('post-audit-active-backlog-statu'!$G$2:$G$6832,A9) -> 372 | C9: =B9/'Audit Dashboard'!$B$6 -> 0.05445762 | D9: Policy resolved; no change | F9: Command access | G9: =COUNTIF('post-audit-active-backlog-statu'!$C$2:$C$6832,F9) -> 499 | H9: =COUNTIFS('post-audit-active-backlog-statu'!$C$2:$C$6832,F9,'post-audit-active-backlog-statu'!$G$2:$G$6832,"Fixed") -> 0 | I9: =COUNTIFS('post-audit-active-backlog-statu'!$C$2:$C$6832,F9,'post-audit-active-backlog-statu'!$G$2:$G$6832,"ReviewedNoChange")+COUNTIFS('post-audit-active-backlog-statu'!$C$2:$C$6832,F9,'post-audit-active-backlog-statu'!$G$2:$G$6832,"SafeNoChange")+COUNTIFS('post-audit-active-backlog-statu'!$C$2:$C$6832,F9,'post-audit-active-backlog-statu'!$G$2:$G$6832,"PolicyResolvedNoChange") -> 484 | J9: =COUNTIFS('post-audit-active-backlog-statu'!$C$2:$C$6832,F9,'post-audit-active-backlog-statu'!$G$2:$G$6832,"BlocksOnlyThisDomain") -> 0 | K9: =H9/G9 -> 0 | M9: Items:Special | N9: =COUNTIF('post-audit-active-backlog-statu'!$D$2:$D$6832,M9) -> 282 | O9: =COUNTIFS('post-audit-active-backlog-statu'!$D$2:$D$6832,M9,'post-audit-active-backlog-statu'!$G$2:$G$6832,"Fixed") -> 5 | P9: =COUNTIFS('post-audit-active-backlog-statu'!$D$2:$D$6832,M9,'post-audit-active-backlog-statu'!$G$2:$G$6832,"ReviewedNoChange")+COUNTIFS('post-audit-active-backlog-statu'!$D$2:$D$6832,M9,'post-audit-active-backlog-statu'!$G$2:$G$6832,"SafeNoChange")+COUNTIFS('post-audit-active-backlog-statu'!$D$2:$D$6832,M9,'post-audit-active-backlog-statu'!$G$2:$G$6832,"PolicyResolvedNoChange") -> 72 | Q9: =COUNTIFS('post-audit-active-backlog-statu'!$D$2:$D$6832,M9,'post-audit-active-backlog-statu'!$G$2:$G$6832,"BlocksOnlyThisDomain") -> 0 | R9: =O9/N9 -> 0.017730496 | T9: 46186 | U9: =COUNTIF('post-audit-active-backlog-statu'!$O$2:$O$6832,TEXT(T9,"yyyy-mm-dd")&"*")+COUNTIFS('post-audit-active-backlog-statu'!$O$2:$O$6832,">="&T9,'post-audit-active-backlog-statu'!$O$2:$O$6832,"<"&T9+1) -> 86 | A9: PolicyResolvedNoChange
B10: =COUNTIF('post-audit-active-backlog-statu'!$G$2:$G$6832,A10) -> 352 | C10: =B10/'Audit Dashboard'!$B$6 -> 0.051529791 | D10: Documented outcome | F10: Pooled enumerables | G10: =COUNTIF('post-audit-active-backlog-statu'!$C$2:$C$6832,F10) -> 408 | H10: =COUNTIFS('post-audit-active-backlog-statu'!$C$2:$C$6832,F10,'post-audit-active-backlog-statu'!$G$2:$G$6832,"Fixed") -> 406 | I10: =COUNTIFS('post-audit-active-backlog-statu'!$C$2:$C$6832,F10,'post-audit-active-backlog-statu'!$G$2:$G$6832,"ReviewedNoChange")+COUNTIFS('post-audit-active-backlog-statu'!$C$2:$C$6832,F10,'post-audit-active-backlog-statu'!$G$2:$G$6832,"SafeNoChange")+COUNTIFS('post-audit-active-backlog-statu'!$C$2:$C$6832,F10,'post-audit-active-backlog-statu'!$G$2:$G$6832,"PolicyResolvedNoChange") -> 0 | J10: =COUNTIFS('post-audit-active-backlog-statu'!$C$2:$C$6832,F10,'post-audit-active-backlog-statu'!$G$2:$G$6832,"BlocksOnlyThisDomain") -> 0 | K10: =H10/G10 -> 0.99509804 | M10: System:Misc | N10: =COUNTIF('post-audit-active-backlog-statu'!$D$2:$D$6832,M10) -> 278 | O10: =COUNTIFS('post-audit-active-backlog-statu'!$D$2:$D$6832,M10,'post-audit-active-backlog-statu'!$G$2:$G$6832,"Fixed") -> 69 | P10: =COUNTIFS('post-audit-active-backlog-statu'!$D$2:$D$6832,M10,'post-audit-active-backlog-statu'!$G$2:$G$6832,"ReviewedNoChange")+COUNTIFS('post-audit-active-backlog-statu'!$D$2:$D$6832,M10,'post-audit-active-backlog-statu'!$G$2:$G$6832,"SafeNoChange")+COUNTIFS('post-audit-active-backlog-statu'!$D$2:$D$6832,M10,'post-audit-active-backlog-statu'!$G$2:$G$6832,"PolicyResolvedNoChange") -> 65 | Q10: =COUNTIFS('post-audit-active-backlog-statu'!$D$2:$D$6832,M10,'post-audit-active-backlog-statu'!$G$2:$G$6832,"BlocksOnlyThisDomain") -> 0 | R10: =O10/N10 -> 0.24820144 | T10: 46187 | U10: =COUNTIF('post-audit-active-backlog-statu'!$O$2:$O$6832,TEXT(T10,"yyyy-mm-dd")&"*")+COUNTIFS('post-audit-active-backlog-statu'!$O$2:$O$6832,">="&T10,'post-audit-active-backlog-statu'!$O$2:$O$6832,"<"&T10+1) -> 5170 | A10: Documented
B11: =COUNTIF('post-audit-active-backlog-statu'!$G$2:$G$6832,A11) -> 330 | C11: =B11/'Audit Dashboard'!$B$6 -> 0.048309179 | D11: False positive | F11: PlayerMobile coupling | G11: =COUNTIF('post-audit-active-backlog-statu'!$C$2:$C$6832,F11) -> 394 | H11: =COUNTIFS('post-audit-active-backlog-statu'!$C$2:$C$6832,F11,'post-audit-active-backlog-statu'!$G$2:$G$6832,"Fixed") -> 0 | I11: =COUNTIFS('post-audit-active-backlog-statu'!$C$2:$C$6832,F11,'post-audit-active-backlog-statu'!$G$2:$G$6832,"ReviewedNoChange")+COUNTIFS('post-audit-active-backlog-statu'!$C$2:$C$6832,F11,'post-audit-active-backlog-statu'!$G$2:$G$6832,"SafeNoChange")+COUNTIFS('post-audit-active-backlog-statu'!$C$2:$C$6832,F11,'post-audit-active-backlog-statu'!$G$2:$G$6832,"PolicyResolvedNoChange") -> 392 | J11: =COUNTIFS('post-audit-active-backlog-statu'!$C$2:$C$6832,F11,'post-audit-active-backlog-statu'!$G$2:$G$6832,"BlocksOnlyThisDomain") -> 0 | K11: =H11/G11 -> 0 | M11: Regions | N11: =COUNTIF('post-audit-active-backlog-statu'!$D$2:$D$6832,M11) -> 259 | O11: =COUNTIFS('post-audit-active-backlog-statu'!$D$2:$D$6832,M11,'post-audit-active-backlog-statu'!$G$2:$G$6832,"Fixed") -> 11 | P11: =COUNTIFS('post-audit-active-backlog-statu'!$D$2:$D$6832,M11,'post-audit-active-backlog-statu'!$G$2:$G$6832,"ReviewedNoChange")+COUNTIFS('post-audit-active-backlog-statu'!$D$2:$D$6832,M11,'post-audit-active-backlog-statu'!$G$2:$G$6832,"SafeNoChange")+COUNTIFS('post-audit-active-backlog-statu'!$D$2:$D$6832,M11,'post-audit-active-backlog-statu'!$G$2:$G$6832,"PolicyResolvedNoChange") -> 220 | Q11: =COUNTIFS('post-audit-active-backlog-statu'!$D$2:$D$6832,M11,'post-audit-active-backlog-statu'!$G$2:$G$6832,"BlocksOnlyThisDomain") -> 0 | R11: =O11/N11 -> 0.042471042 | T11: 46188 | U11: =COUNTIF('post-audit-active-backlog-statu'!$O$2:$O$6832,TEXT(T11,"yyyy-mm-dd")&"*")+COUNTIFS('post-audit-active-backlog-statu'!$O$2:$O$6832,">="&T11,'post-audit-active-backlog-statu'!$O$2:$O$6832,"<"&T11+1) -> 549 | A11: FalsePositive
B12: =COUNTIF('post-audit-active-backlog-statu'!$G$2:$G$6832,A12) -> 83 | C12: =B12/'Audit Dashboard'!$B$6 -> 0.01215049 | D12: Accepted boundary/fence | F12: XML/config schemas | G12: =COUNTIF('post-audit-active-backlog-statu'!$C$2:$C$6832,F12) -> 232 | H12: =COUNTIFS('post-audit-active-backlog-statu'!$C$2:$C$6832,F12,'post-audit-active-backlog-statu'!$G$2:$G$6832,"Fixed") -> 0 | I12: =COUNTIFS('post-audit-active-backlog-statu'!$C$2:$C$6832,F12,'post-audit-active-backlog-statu'!$G$2:$G$6832,"ReviewedNoChange")+COUNTIFS('post-audit-active-backlog-statu'!$C$2:$C$6832,F12,'post-audit-active-backlog-statu'!$G$2:$G$6832,"SafeNoChange")+COUNTIFS('post-audit-active-backlog-statu'!$C$2:$C$6832,F12,'post-audit-active-backlog-statu'!$G$2:$G$6832,"PolicyResolvedNoChange") -> 0 | J12: =COUNTIFS('post-audit-active-backlog-statu'!$C$2:$C$6832,F12,'post-audit-active-backlog-statu'!$G$2:$G$6832,"BlocksOnlyThisDomain") -> 0 | K12: =H12/G12 -> 0 | M12: Government | N12: =COUNTIF('post-audit-active-backlog-statu'!$D$2:$D$6832,M12) -> 252 | O12: =COUNTIFS('post-audit-active-backlog-statu'!$D$2:$D$6832,M12,'post-audit-active-backlog-statu'!$G$2:$G$6832,"Fixed") -> 8 | P12: =COUNTIFS('post-audit-active-backlog-statu'!$D$2:$D$6832,M12,'post-audit-active-backlog-statu'!$G$2:$G$6832,"ReviewedNoChange")+COUNTIFS('post-audit-active-backlog-statu'!$D$2:$D$6832,M12,'post-audit-active-backlog-statu'!$G$2:$G$6832,"SafeNoChange")+COUNTIFS('post-audit-active-backlog-statu'!$D$2:$D$6832,M12,'post-audit-active-backlog-statu'!$G$2:$G$6832,"PolicyResolvedNoChange") -> 237 | Q12: =COUNTIFS('post-audit-active-backlog-statu'!$D$2:$D$6832,M12,'post-audit-active-backlog-statu'!$G$2:$G$6832,"BlocksOnlyThisDomain") -> 1 | R12: =O12/N12 -> 0.031746032 | T12: 46312 | U12: =COUNTIF('post-audit-active-backlog-statu'!$O$2:$O$6832,TEXT(T12,"yyyy-mm-dd")&"*")+COUNTIFS('post-audit-active-backlog-statu'!$O$2:$O$6832,">="&T12,'post-audit-active-backlog-statu'!$O$2:$O$6832,"<"&T12+1) -> 6 | A12: AcceptedFence
B13: =COUNTIF('post-audit-active-backlog-statu'!$G$2:$G$6832,A13) -> 7 | C13: =B13/'Audit Dashboard'!$B$6 -> 0.0010247402 | D13: Domain-specific blocker | F13: Documentation contradictions | G13: =COUNTIF('post-audit-active-backlog-statu'!$C$2:$C$6832,F13) -> 158 | H13: =COUNTIFS('post-audit-active-backlog-statu'!$C$2:$C$6832,F13,'post-audit-active-backlog-statu'!$G$2:$G$6832,"Fixed") -> 25 | I13: =COUNTIFS('post-audit-active-backlog-statu'!$C$2:$C$6832,F13,'post-audit-active-backlog-statu'!$G$2:$G$6832,"ReviewedNoChange")+COUNTIFS('post-audit-active-backlog-statu'!$C$2:$C$6832,F13,'post-audit-active-backlog-statu'!$G$2:$G$6832,"SafeNoChange")+COUNTIFS('post-audit-active-backlog-statu'!$C$2:$C$6832,F13,'post-audit-active-backlog-statu'!$G$2:$G$6832,"PolicyResolvedNoChange") -> 7 | J13: =COUNTIFS('post-audit-active-backlog-statu'!$C$2:$C$6832,F13,'post-audit-active-backlog-statu'!$G$2:$G$6832,"BlocksOnlyThisDomain") -> 0 | K13: =H13/G13 -> 0.15822785 | M13: Invasion | N13: =COUNTIF('post-audit-active-backlog-statu'!$D$2:$D$6832,M13) -> 212 | O13: =COUNTIFS('post-audit-active-backlog-statu'!$D$2:$D$6832,M13,'post-audit-active-backlog-statu'!$G$2:$G$6832,"Fixed") -> 1 | P13: =COUNTIFS('post-audit-active-backlog-statu'!$D$2:$D$6832,M13,'post-audit-active-backlog-statu'!$G$2:$G$6832,"ReviewedNoChange")+COUNTIFS('post-audit-active-backlog-statu'!$D$2:$D$6832,M13,'post-audit-active-backlog-statu'!$G$2:$G$6832,"SafeNoChange")+COUNTIFS('post-audit-active-backlog-statu'!$D$2:$D$6832,M13,'post-audit-active-backlog-statu'!$G$2:$G$6832,"PolicyResolvedNoChange") -> 200 | Q13: =COUNTIFS('post-audit-active-backlog-statu'!$D$2:$D$6832,M13,'post-audit-active-backlog-statu'!$G$2:$G$6832,"BlocksOnlyThisDomain") -> 1 | R13: =O13/N13 -> 0.0047169811 | A13: BlocksOnlyThisDomain | T13: 46313 | U13: =COUNTIF('post-audit-active-backlog-statu'!$O$2:$O$6832,TEXT(T13,"yyyy-mm-dd")&"*")+COUNTIFS('post-audit-active-backlog-statu'!$O$2:$O$6832,">="&T13,'post-audit-active-backlog-statu'!$O$2:$O$6832,"<"&T13+1) -> 1
F14: WriteReadAlignment | B14: =COUNTIF('post-audit-active-backlog-statu'!$G$2:$G$6832,A14) -> 0 | C14: =B14/'Audit Dashboard'!B6 -> 0 | G14: =COUNTIF('post-audit-active-backlog-statu'!$C$2:$C$6832,F14) -> 153 | H14: =COUNTIFS('post-audit-active-backlog-statu'!$C$2:$C$6832,F14,'post-audit-active-backlog-statu'!$G$2:$G$6832,"Fixed") -> 4 | I14: =COUNTIFS('post-audit-active-backlog-statu'!$C$2:$C$6832,F14,'post-audit-active-backlog-statu'!$G$2:$G$6832,"ReviewedNoChange")+COUNTIFS('post-audit-active-backlog-statu'!$C$2:$C$6832,F14,'post-audit-active-backlog-statu'!$G$2:$G$6832,"SafeNoChange")+COUNTIFS('post-audit-active-backlog-statu'!$C$2:$C$6832,F14,'post-audit-active-backlog-statu'!$G$2:$G$6832,"PolicyResolvedNoChange") -> 101 | J14: =COUNTIFS('post-audit-active-backlog-statu'!$C$2:$C$6832,F14,'post-audit-active-backlog-statu'!$G$2:$G$6832,"BlocksOnlyThisDomain") -> 0 | K14: =H14/G14 -> 0.026143791 | M14: Items:Misc | N14: =COUNTIF('post-audit-active-backlog-statu'!$D$2:$D$6832,M14) -> 207 | O14: =COUNTIFS('post-audit-active-backlog-statu'!$D$2:$D$6832,M14,'post-audit-active-backlog-statu'!$G$2:$G$6832,"Fixed") -> 32 | P14: =COUNTIFS('post-audit-active-backlog-statu'!$D$2:$D$6832,M14,'post-audit-active-backlog-statu'!$G$2:$G$6832,"ReviewedNoChange")+COUNTIFS('post-audit-active-backlog-statu'!$D$2:$D$6832,M14,'post-audit-active-backlog-statu'!$G$2:$G$6832,"SafeNoChange")+COUNTIFS('post-audit-active-backlog-statu'!$D$2:$D$6832,M14,'post-audit-active-backlog-statu'!$G$2:$G$6832,"PolicyResolvedNoChange") -> 127 | Q14: =COUNTIFS('post-audit-active-backlog-statu'!$D$2:$D$6832,M14,'post-audit-active-backlog-statu'!$G$2:$G$6832,"BlocksOnlyThisDomain") -> 0 | R14: =O14/N14 -> 0.15458937 | T14: 46314 | U14: =COUNTIF('post-audit-active-backlog-statu'!$O$2:$O$6832,TEXT(T14,"yyyy-mm-dd")&"*")+COUNTIFS('post-audit-active-backlog-statu'!$O$2:$O$6832,">="&T14,'post-audit-active-backlog-statu'!$O$2:$O$6832,"<"&T14+1) -> 2 | A14: Deferred
A15: Open | B15: =COUNTIF('post-audit-active-backlog-statu'!$G$2:$G$6832,A15) -> 7 | C15: =B15/'Audit Dashboard'!B6 -> 0.0010247402 | D15: Work or required acceptance remains open | F15: Staff tooling | G15: =COUNTIF('post-audit-active-backlog-statu'!$C$2:$C$6832,F15) -> 125 | H15: =COUNTIFS('post-audit-active-backlog-statu'!$C$2:$C$6832,F15,'post-audit-active-backlog-statu'!$G$2:$G$6832,"Fixed") -> 86 | I15: =COUNTIFS('post-audit-active-backlog-statu'!$C$2:$C$6832,F15,'post-audit-active-backlog-statu'!$G$2:$G$6832,"ReviewedNoChange")+COUNTIFS('post-audit-active-backlog-statu'!$C$2:$C$6832,F15,'post-audit-active-backlog-statu'!$G$2:$G$6832,"SafeNoChange")+COUNTIFS('post-audit-active-backlog-statu'!$C$2:$C$6832,F15,'post-audit-active-backlog-statu'!$G$2:$G$6832,"PolicyResolvedNoChange") -> 6 | J15: =COUNTIFS('post-audit-active-backlog-statu'!$C$2:$C$6832,F15,'post-audit-active-backlog-statu'!$G$2:$G$6832,"BlocksOnlyThisDomain") -> 0 | K15: =H15/G15 -> 0.688 | M15: Spell Framework | N15: =COUNTIF('post-audit-active-backlog-statu'!$D$2:$D$6832,M15) -> 186 | O15: =COUNTIFS('post-audit-active-backlog-statu'!$D$2:$D$6832,M15,'post-audit-active-backlog-statu'!$G$2:$G$6832,"Fixed") -> 18 | P15: =COUNTIFS('post-audit-active-backlog-statu'!$D$2:$D$6832,M15,'post-audit-active-backlog-statu'!$G$2:$G$6832,"ReviewedNoChange")+COUNTIFS('post-audit-active-backlog-statu'!$D$2:$D$6832,M15,'post-audit-active-backlog-statu'!$G$2:$G$6832,"SafeNoChange")+COUNTIFS('post-audit-active-backlog-statu'!$D$2:$D$6832,M15,'post-audit-active-backlog-statu'!$G$2:$G$6832,"PolicyResolvedNoChange") -> 167 | Q15: =COUNTIFS('post-audit-active-backlog-statu'!$D$2:$D$6832,M15,'post-audit-active-backlog-statu'!$G$2:$G$6832,"BlocksOnlyThisDomain") -> 0 | R15: =O15/N15 -> 0.096774194 | T15: 46315 | U15: =COUNTIF('post-audit-active-backlog-statu'!$O$2:$O$6832,TEXT(T15,"yyyy-mm-dd")&"*")+COUNTIFS('post-audit-active-backlog-statu'!$O$2:$O$6832,">="&T15,'post-audit-active-backlog-statu'!$O$2:$O$6832,"<"&T15+1) -> 2
F16: Region and map assumptions | G16: =COUNTIF('post-audit-active-backlog-statu'!$C$2:$C$6832,F16) -> 112 | H16: =COUNTIFS('post-audit-active-backlog-statu'!$C$2:$C$6832,F16,'post-audit-active-backlog-statu'!$G$2:$G$6832,"Fixed") -> 0 | I16: =COUNTIFS('post-audit-active-backlog-statu'!$C$2:$C$6832,F16,'post-audit-active-backlog-statu'!$G$2:$G$6832,"ReviewedNoChange")+COUNTIFS('post-audit-active-backlog-statu'!$C$2:$C$6832,F16,'post-audit-active-backlog-statu'!$G$2:$G$6832,"SafeNoChange")+COUNTIFS('post-audit-active-backlog-statu'!$C$2:$C$6832,F16,'post-audit-active-backlog-statu'!$G$2:$G$6832,"PolicyResolvedNoChange") -> 88 | J16: =COUNTIFS('post-audit-active-backlog-statu'!$C$2:$C$6832,F16,'post-audit-active-backlog-statu'!$G$2:$G$6832,"BlocksOnlyThisDomain") -> 0 | K16: =H16/G16 -> 0 | M16: ServerCore | N16: =COUNTIF('post-audit-active-backlog-statu'!$D$2:$D$6832,M16) -> 183 | O16: =COUNTIFS('post-audit-active-backlog-statu'!$D$2:$D$6832,M16,'post-audit-active-backlog-statu'!$G$2:$G$6832,"Fixed") -> 1 | P16: =COUNTIFS('post-audit-active-backlog-statu'!$D$2:$D$6832,M16,'post-audit-active-backlog-statu'!$G$2:$G$6832,"ReviewedNoChange")+COUNTIFS('post-audit-active-backlog-statu'!$D$2:$D$6832,M16,'post-audit-active-backlog-statu'!$G$2:$G$6832,"SafeNoChange")+COUNTIFS('post-audit-active-backlog-statu'!$D$2:$D$6832,M16,'post-audit-active-backlog-statu'!$G$2:$G$6832,"PolicyResolvedNoChange") -> 102 | Q16: =COUNTIFS('post-audit-active-backlog-statu'!$D$2:$D$6832,M16,'post-audit-active-backlog-statu'!$G$2:$G$6832,"BlocksOnlyThisDomain") -> 0 | R16: =O16/N16 -> 0.0054644809 | T16: 46320 | U16: =COUNTIF('post-audit-active-backlog-statu'!$O$2:$O$6832,TEXT(T16,"yyyy-mm-dd")&"*")+COUNTIFS('post-audit-active-backlog-statu'!$O$2:$O$6832,">="&T16,'post-audit-active-backlog-statu'!$O$2:$O$6832,"<"&T16+1) -> 7
F17: Project include drift | G17: =COUNTIF('post-audit-active-backlog-statu'!$C$2:$C$6832,F17) -> 61 | H17: =COUNTIFS('post-audit-active-backlog-statu'!$C$2:$C$6832,F17,'post-audit-active-backlog-statu'!$G$2:$G$6832,"Fixed") -> 61 | I17: =COUNTIFS('post-audit-active-backlog-statu'!$C$2:$C$6832,F17,'post-audit-active-backlog-statu'!$G$2:$G$6832,"ReviewedNoChange")+COUNTIFS('post-audit-active-backlog-statu'!$C$2:$C$6832,F17,'post-audit-active-backlog-statu'!$G$2:$G$6832,"SafeNoChange")+COUNTIFS('post-audit-active-backlog-statu'!$C$2:$C$6832,F17,'post-audit-active-backlog-statu'!$G$2:$G$6832,"PolicyResolvedNoChange") -> 0 | J17: =COUNTIFS('post-audit-active-backlog-statu'!$C$2:$C$6832,F17,'post-audit-active-backlog-statu'!$G$2:$G$6832,"BlocksOnlyThisDomain") -> 0 | K17: =H17/G17 -> 1 | M17: Vendor Core | N17: =COUNTIF('post-audit-active-backlog-statu'!$D$2:$D$6832,M17) -> 151 | O17: =COUNTIFS('post-audit-active-backlog-statu'!$D$2:$D$6832,M17,'post-audit-active-backlog-statu'!$G$2:$G$6832,"Fixed") -> 4 | P17: =COUNTIFS('post-audit-active-backlog-statu'!$D$2:$D$6832,M17,'post-audit-active-backlog-statu'!$G$2:$G$6832,"ReviewedNoChange")+COUNTIFS('post-audit-active-backlog-statu'!$D$2:$D$6832,M17,'post-audit-active-backlog-statu'!$G$2:$G$6832,"SafeNoChange")+COUNTIFS('post-audit-active-backlog-statu'!$D$2:$D$6832,M17,'post-audit-active-backlog-statu'!$G$2:$G$6832,"PolicyResolvedNoChange") -> 132 | Q17: =COUNTIFS('post-audit-active-backlog-statu'!$D$2:$D$6832,M17,'post-audit-active-backlog-statu'!$G$2:$G$6832,"BlocksOnlyThisDomain") -> 0 | R17: =O17/N17 -> 0.026490066
